<?xml version="1.0" ?>
<!-- =================================================================================== -->
<!-- |    This document was autogenerated by xacro from /home/csl/ros_ws/sim-scene/src/scene/model/xacro/sim-robot.xacro | -->
<!-- |    EDITING THIS FILE BY HAND IS NOT RECOMMENDED                                 | -->
<!-- =================================================================================== -->
<robot name="sim-robot">
  <!-- foot base link -->
  <link name="base_footprint">
    <visual>
      <geometry>
        <box size="0.001 0.001 0.001"/>
      </geometry>
      <material name="black">
        <color rgba="0.0 0.0 0.0 0.8"/>
      </material>
    </visual>
  </link>
  <gazebo reference="base_footprint">
    <material>Gazebo/Black</material>
  </gazebo>
  <gazebo>
    <plugin filename="libgazebo_ros_p3d.so" name="base_footprint_pose">
      <alwaysOn>true</alwaysOn>
      <updateRate>50.0</updateRate>
      <bodyName>base_footprint</bodyName>
      <topicName>base_footprint_ground_truth</topicName>
      <gaussianNoise>0.0</gaussianNoise>
      <frameName>map</frameName>
      <xyzOffsets>0 0 0</xyzOffsets>
      <rpyOffsets>0 0 0</rpyOffsets>
    </plugin>
  </gazebo>
  <!-- base link -->
  <link name="base_link">
    <visual>
      <geometry>
        <box size="0.3 0.3 0.3"/>
      </geometry>
      <material name="white">
        <color rgba="1.0 1.0 1.0 0.8"/>
      </material>
    </visual>
    <collision>
      <geometry>
        <box size="0.3 0.3 0.3"/>
      </geometry>
      <origin rpy="0.0 0.0 0.0" xyz="0.0 0.0 0.0"/>
    </collision>
    <inertial>
      <mass value="0.5"/>
      <inertia ixx="0.0075" ixy="0" ixz="0" iyy="0.0075" iyz="0" izz="0.0075"/>
    </inertial>
  </link>
  <gazebo reference="base_link">
    <material>Gazebo/White</material>
  </gazebo>
  <!-- joint -->
  <joint name="base_to_foot" type="fixed">
    <parent link="base_footprint"/>
    <child link="base_link"/>
    <origin rpy="0.0 0.0 0.0" xyz="0.0 0.0 0.18"/>
    <axis xyz="0.0 0.0 1.0"/>
  </joint>
  <!-- lidar -->
  <link name="arm">
    <visual>
      <geometry>
        <cylinder length="0.1" radius="0.01"/>
      </geometry>
      <origin rpy="0.0 0.0 0.0" xyz="0.0 0.0 0.0"/>
      <material name="black">
        <color rgba="0.0 0.0 0.0 0.8"/>
      </material>
    </visual>
    <collision>
      <geometry>
        <cylinder length="0.1" radius="0.01"/>
      </geometry>
      <origin rpy="0.0 0.0 0.0" xyz="0.0 0.0 0.0"/>
    </collision>
    <inertial>
      <mass value="0.01"/>
      <inertia ixx="8.583333333333335e-06" ixy="0" ixz="0" iyy="8.583333333333335e-06" iyz="0" izz="5.000000000000001e-07"/>
    </inertial>
  </link>
  <!-- joint -->
  <joint name="arm_to_base_link" type="fixed">
    <parent link="base_link"/>
    <child link="arm"/>
    <origin rpy="0.0 0.0 0.0" xyz="0.0 0.0 0.2"/>
    <axis xyz="0.0 0.0 1.0"/>
  </joint>
  <gazebo reference="arm">
    <material>Gazebo/Black</material>
  </gazebo>
  <!-- lidar -->
  <link name="lidar">
    <visual>
      <geometry>
        <cylinder length="0.05" radius="0.05"/>
      </geometry>
      <origin rpy="0.0 0.0 0.0" xyz="0.0 0.0 0.0"/>
      <material name="red">
        <color rgba="1.0 0.0 0.0 0.8"/>
      </material>
    </visual>
    <collision>
      <geometry>
        <cylinder length="0.05" radius="0.05"/>
      </geometry>
      <origin rpy="0.0 0.0 0.0" xyz="0.0 0.0 0.0"/>
    </collision>
    <inertial>
      <mass value="0.02"/>
      <inertia ixx="1.666666666666667e-05" ixy="0" ixz="0" iyy="1.666666666666667e-05" iyz="0" izz="2.5e-05"/>
    </inertial>
  </link>
  <!-- joint -->
  <joint name="lidar_to_arm" type="fixed">
    <parent link="arm"/>
    <child link="lidar"/>
    <origin rpy="0.0 0.0 0.0" xyz="0.0 0.0 0.07500000000000001"/>
    <axis xyz="0.0 0.0 1.0"/>
  </joint>
  <gazebo reference="lidar">
    <material>Gazebo/Red</material>
  </gazebo>
  <!-- imu -->
  <link name="imu">
    <visual>
      <geometry>
        <box size="0.06 0.06 0.06"/>
      </geometry>
      <origin rpy="0.0 0.0 0.0" xyz="0.0 0.0 0.0"/>
      <material name="green">
        <color rgba="0.0 1.0 0.0 0.8"/>
      </material>
    </visual>
    <collision>
      <geometry>
        <box size="0.06 0.06 0.06"/>
      </geometry>
      <origin rpy="0.0 0.0 0.0" xyz="0.0 0.0 0.0"/>
    </collision>
    <inertial>
      <mass value="0.01"/>
      <inertia ixx="6e-06" ixy="0" ixz="0" iyy="6e-06" iyz="0" izz="6e-06"/>
    </inertial>
  </link>
  <!-- joint -->
  <joint name="imu_to_base_link" type="fixed">
    <parent link="base_link"/>
    <child link="imu"/>
    <origin rpy="0.0 0.0 0.0" xyz="-0.18 0.0 0.0"/>
    <axis xyz="0.0 0.0 1.0"/>
  </joint>
  <gazebo reference="imu">
    <material>Gazebo/Green</material>
  </gazebo>
  <!-- camera -->
  <link name="camera">
    <visual>
      <geometry>
        <box size="0.06 0.06 0.06"/>
      </geometry>
      <origin rpy="0.0 0.0 0.0" xyz="0.0 0.0 0.0"/>
      <material name="blue">
        <color rgba="0.0 0.0 1.0 0.8"/>
      </material>
    </visual>
    <collision>
      <geometry>
        <box size="0.06 0.06 0.06"/>
      </geometry>
      <origin rpy="0.0 0.0 0.0" xyz="0.0 0.0 0.0"/>
    </collision>
    <inertial>
      <mass value="0.01"/>
      <inertia ixx="6e-06" ixy="0" ixz="0" iyy="6e-06" iyz="0" izz="6e-06"/>
    </inertial>
  </link>
  <!-- joint -->
  <joint name="camera_to_base_link" type="fixed">
    <parent link="base_link"/>
    <child link="camera"/>
    <origin rpy="0.0 0.0 0.0" xyz="0.18 0.0 0.0"/>
    <axis xyz="0.0 0.0 1.0"/>
  </joint>
  <gazebo reference="camera">
    <material>Gazebo/Blue</material>
  </gazebo>
  <gazebo reference="lidar">
    <sensor name="vodyne16" type="ray">
      <pose>0 0 0 0 0 0</pose>
      <visualize>false</visualize>
      <update_rate>20.0</update_rate>
      <ray>
        <scan>
          <horizontal>
            <samples>1800</samples>
            <resolution>0.2</resolution>
            <min_angle>-3.1415926535</min_angle>
            <max_angle> 3.1415926535</max_angle>
          </horizontal>
          <vertical>
            <samples>16</samples>
            <resolution>2</resolution>
            <min_angle>-0.26179938779166667</min_angle>
            <max_angle> 0.26179938779166667</max_angle>
          </vertical>
        </scan>
        <range>
          <min>0.10</min>
          <max>30.0</max>
          <resolution>0.001</resolution>
        </range>
        <noise>
          <type>gaussian</type>
          <mean>0.0</mean>
          <stddev>0.000</stddev>
        </noise>
      </ray>
      <plugin filename="libgazebo_ros_velodyne_laser.so" name="gazebo_rplidar">
        <topicName>/sim_lidar/scan</topicName>
        <frameName>/lidar</frameName>
        <organize_cloud>true</organize_cloud>
        <min_range>0.10</min_range>
        <max_range>30.0</max_range>
        <gaussianNoise>0.0</gaussianNoise>
      </plugin>
    </sensor>
  </gazebo>
  <gazebo>
    <plugin filename="libgazebo_ros_p3d.so" name="lidar_pose">
      <alwaysOn>true</alwaysOn>
      <updateRate>50.0</updateRate>
      <bodyName>lidar</bodyName>
      <topicName>lidar_ground_truth</topicName>
      <gaussianNoise>0.0</gaussianNoise>
      <frameName>map</frameName>
      <xyzOffsets>0 0 0</xyzOffsets>
      <rpyOffsets>0 0 0</rpyOffsets>
    </plugin>
  </gazebo>
  <gazebo reference="imu">
    <gravity>true</gravity>
    <sensor name="imu_sensor" type="imu">
      <always_on>true</always_on>
      <update_rate>400</update_rate>
      <visualize>true</visualize>
      <topic>__default_topic__</topic>
      <plugin filename="libgazebo_ros_imu_sensor.so" name="imu_plugin">
        <topicName>/sim_imu/frame</topicName>
        <bodyName>imu</bodyName>
        <updateRateHZ>400</updateRateHZ>
        <gaussianNoise>0.0</gaussianNoise>
        <xyzOffset>0 0 0</xyzOffset>
        <rpyOffset>0 0 0</rpyOffset>
        <frameName>imu</frameName>
        <initialOrientationAsReference>false</initialOrientationAsReference>
      </plugin>
      <pose>0 0 0 0 0 0</pose>
    </sensor>
  </gazebo>
  <gazebo>
    <plugin filename="libgazebo_ros_p3d.so" name="imu_pose">
      <alwaysOn>true</alwaysOn>
      <updateRate>50.0</updateRate>
      <bodyName>imu</bodyName>
      <topicName>imu_ground_truth</topicName>
      <gaussianNoise>0.0</gaussianNoise>
      <frameName>map</frameName>
      <xyzOffsets>0 0 0</xyzOffsets>
      <rpyOffsets>0 0 0</rpyOffsets>
    </plugin>
  </gazebo>
  <gazebo reference="camera">
    <sensor name="camera_node" type="camera">
      <update_rate>30.0</update_rate>
      <camera name="head">
        <horizontal_fov>1.3962634</horizontal_fov>
        <image>
          <width>1280</width>
          <height>720</height>
          <format>R8G8B8</format>
        </image>
        <clip>
          <near>0.02</near>
          <far>300</far>
        </clip>
        <noise>
          <type>gaussian</type>
          <mean>0.0</mean>
          <stddev>0.0</stddev>
        </noise>
      </camera>
      <plugin filename="libgazebo_ros_camera.so" name="gazebo_camera">
        <alwaysOn>true</alwaysOn>
        <updateRate>0.0</updateRate>
        <cameraName>/sim_camera</cameraName>
        <imageTopicName>image</imageTopicName>
        <cameraInfoTopicName>camera_info</cameraInfoTopicName>
        <frameName>camera</frameName>
        <hackBaseline>0.07</hackBaseline>
        <distortionK1>0.0</distortionK1>
        <distortionK2>0.0</distortionK2>
        <distortionK3>0.0</distortionK3>
        <distortionT1>0.0</distortionT1>
        <distortionT2>0.0</distortionT2>
      </plugin>
    </sensor>
  </gazebo>
  <gazebo>
    <plugin filename="libgazebo_ros_p3d.so" name="camera_pose">
      <alwaysOn>true</alwaysOn>
      <updateRate>50.0</updateRate>
      <bodyName>camera</bodyName>
      <topicName>camera_ground_truth</topicName>
      <gaussianNoise>0.0</gaussianNoise>
      <frameName>map</frameName>
      <xyzOffsets>0 0 0</xyzOffsets>
      <rpyOffsets>0 0 0</rpyOffsets>
    </plugin>
  </gazebo>
  <!-- wheels -->
  <link name="left_wheel">
    <visual>
      <geometry>
        <cylinder length="0.04" radius="0.08"/>
      </geometry>
      <origin rpy="1.57079632675 0.0 0.0" xyz="0.0 0.0 0.0"/>
      <material name="black">
        <color rgba="0.0 0.0 0.0 0.8"/>
      </material>
    </visual>
    <collision>
      <geometry>
        <cylinder length="0.04" radius="0.08"/>
      </geometry>
      <origin rpy="1.57079632675 0.0 0.0" xyz="0.0 0.0 0.0"/>
    </collision>
    <inertial>
      <mass value="2.0"/>
      <inertia ixx="0.0034666666666666665" ixy="0" ixz="0" iyy="0.0034666666666666665" iyz="0" izz="0.0064"/>
    </inertial>
  </link>
  <!-- joint -->
  <joint name="left_wheel_to_base_link" type="continuous">
    <parent link="base_link"/>
    <child link="left_wheel"/>
    <origin xyz="0.0 0.15 -0.09999999999999999"/>
    <axis xyz="0 1 0"/>
  </joint>
  <gazebo reference="left_wheel">
    <material>Gazebo/Black</material>
  </gazebo>
  <link name="right_wheel">
    <visual>
      <geometry>
        <cylinder length="0.04" radius="0.08"/>
      </geometry>
      <origin rpy="1.57079632675 0.0 0.0" xyz="0.0 0.0 0.0"/>
      <material name="black">
        <color rgba="0.0 0.0 0.0 0.8"/>
      </material>
    </visual>
    <collision>
      <geometry>
        <cylinder length="0.04" radius="0.08"/>
      </geometry>
      <origin rpy="1.57079632675 0.0 0.0" xyz="0.0 0.0 0.0"/>
    </collision>
    <inertial>
      <mass value="2.0"/>
      <inertia ixx="0.0034666666666666665" ixy="0" ixz="0" iyy="0.0034666666666666665" iyz="0" izz="0.0064"/>
    </inertial>
  </link>
  <!-- joint -->
  <joint name="right_wheel_to_base_link" type="continuous">
    <parent link="base_link"/>
    <child link="right_wheel"/>
    <origin xyz="0.0 -0.15 -0.09999999999999999"/>
    <axis xyz="0 1 0"/>
  </joint>
  <gazebo reference="right_wheel">
    <material>Gazebo/Black</material>
  </gazebo>
  <link name="front_support_wheel">
    <visual>
      <geometry>
        <sphere radius="0.015"/>
      </geometry>
      <origin rpy="0.0 0.0 0.0" xyz="0.0 0.0 0.0"/>
      <material name="black">
        <color rgba="0.0 0.0 0.0 0.8"/>
      </material>
    </visual>
    <collision>
      <geometry>
        <sphere radius="0.015"/>
      </geometry>
      <origin rpy="0.0 0.0 0.0" xyz="0.0 0.0 0.0"/>
    </collision>
    <inertial>
      <mass value="2.0"/>
      <inertia ixx="0.00017999999999999998" ixy="0" ixz="0" iyy="0.00017999999999999998" iyz="0" izz="0.00017999999999999998"/>
    </inertial>
  </link>
  <!-- joint -->
  <joint name="front_support_wheel_to_base_link" type="continuous">
    <parent link="base_link"/>
    <child link="front_support_wheel"/>
    <origin xyz="0.135 0.0 -0.16499999999999998"/>
    <axis xyz="1 1 1"/>
  </joint>
  <gazebo reference="front_support_wheel">
    <material>Gazebo/Black</material>
  </gazebo>
  <link name="back_support_wheel">
    <visual>
      <geometry>
        <sphere radius="0.015"/>
      </geometry>
      <origin rpy="0.0 0.0 0.0" xyz="0.0 0.0 0.0"/>
      <material name="black">
        <color rgba="0.0 0.0 0.0 0.8"/>
      </material>
    </visual>
    <collision>
      <geometry>
        <sphere radius="0.015"/>
      </geometry>
      <origin rpy="0.0 0.0 0.0" xyz="0.0 0.0 0.0"/>
    </collision>
    <inertial>
      <mass value="2.0"/>
      <inertia ixx="0.00017999999999999998" ixy="0" ixz="0" iyy="0.00017999999999999998" iyz="0" izz="0.00017999999999999998"/>
    </inertial>
  </link>
  <!-- joint -->
  <joint name="back_support_wheel_to_base_link" type="continuous">
    <parent link="base_link"/>
    <child link="back_support_wheel"/>
    <origin xyz="-0.135 0.0 -0.16499999999999998"/>
    <axis xyz="1 1 1"/>
  </joint>
  <gazebo reference="back_support_wheel">
    <material>Gazebo/Black</material>
  </gazebo>
  <!-- Transmission is important to link the joints and the controller -->
  <transmission name="left_wheel_to_base_link_trans">
    <type>transmission_interface/SimpleTransmission</type>
    <joint name="left_wheel_to_base_link">
      <hardwareInterface>hardware_interface/VelocityJointInterface</hardwareInterface>
    </joint>
    <actuator name="left_wheel_to_base_link_motor">
      <hardwareInterface>hardware_interface/VelocityJointInterface</hardwareInterface>
      <mechanicalReduction>1</mechanicalReduction>
    </actuator>
  </transmission>
  <!-- Transmission is important to link the joints and the controller -->
  <transmission name="right_wheel_to_base_link_trans">
    <type>transmission_interface/SimpleTransmission</type>
    <joint name="right_wheel_to_base_link">
      <hardwareInterface>hardware_interface/VelocityJointInterface</hardwareInterface>
    </joint>
    <actuator name="right_wheel_to_base_link_motor">
      <hardwareInterface>hardware_interface/VelocityJointInterface</hardwareInterface>
      <mechanicalReduction>1</mechanicalReduction>
    </actuator>
  </transmission>
  <gazebo>
    <plugin filename="libgazebo_ros_diff_drive.so" name="differential_drive_controller">
      <rosDebugLevel>Debug</rosDebugLevel>
      <publishWheelTF>false</publishWheelTF>
      <robotNamespace>/</robotNamespace>
      <publishTf>1</publishTf>
      <publishWheelJointState>false</publishWheelJointState>
      <publishOdomTF>true</publishOdomTF>
      <odometrySource>world</odometrySource>
      <alwaysOn>true</alwaysOn>
      <updateRate>100.0</updateRate>
      <legacyMode>true</legacyMode>
      <leftJoint>left_wheel_to_base_link</leftJoint>
      <rightJoint>right_wheel_to_base_link</rightJoint>
      <wheelSeparation>0.3</wheelSeparation>
      <wheelDiameter>0.16</wheelDiameter>
      <broadcastTF>1</broadcastTF>
      <wheelTorque>30</wheelTorque>
      <wheelAcceleration>1.8</wheelAcceleration>
      <commandTopic>cmd_vel</commandTopic>
      <odometryFrame>map</odometryFrame>
      <odometryTopic>odom</odometryTopic>
      <robotBaseFrame>base_footprint</robotBaseFrame>
    </plugin>
  </gazebo>
</robot>

